<?xml version="1.0" encoding="utf-8"?>
<!-- This URDF was automatically created by SolidWorks to URDF Exporter! Originally created by Stephen Brawner (brawner@gmail.com) 
     Commit Version: 1.6.0-4-g7f85cfe  Build Version: 1.6.7995.38578
     For more information, please see http://wiki.ros.org/sw_urdf_exporter -->
<robot
  name="scara">
  <link
    name="base_link">
    <inertial>
      <origin
        xyz="-0.021177 -1.7347E-18 0.38618"
        rpy="0 0 0" />
      <mass
        value="1.695" />
      <inertia
        ixx="0.10082"
        ixy="1.326E-19"
        ixz="0.000855"
        iyy="0.10086"
        iyz="4.437E-19"
        izz="0.00073725" />
    </inertial>
    <visual>
      <origin
        xyz="0 0 0"
        rpy="0 0 0" />
      <geometry>
        <mesh
          filename="package://scara.SLDASM/meshes/base_link.STL" />
      </geometry>
      <material
        name="">
        <color
          rgba="1 1 1 1" />
      </material>
    </visual>
    <collision>
      <origin
        xyz="0 0 0"
        rpy="0 0 0" />
      <geometry>
        <mesh
          filename="package://scara.SLDASM/meshes/base_link.STL" />
      </geometry>
    </collision>
  </link>
  <link
    name="link1">
    <inertial>
      <origin
        xyz="0.020827 7.8837E-10 0.0024752"
        rpy="0 0 0" />
      <mass
        value="0.05093" />
      <inertia
        ixx="1.1209E-05"
        ixy="-5.5952E-13"
        ixz="-1.7182E-06"
        iyy="1.2277E-05"
        iyz="2.6885E-13"
        izz="1.7263E-05" />
    </inertial>
    <visual>
      <origin
        xyz="0 0 0"
        rpy="0 0 0" />
      <geometry>
        <mesh
          filename="package://scara.SLDASM/meshes/link1.STL" />
      </geometry>
      <material
        name="">
        <color
          rgba="1 1 1 1" />
      </material>
    </visual>
    <collision>
      <origin
        xyz="0 0 0"
        rpy="0 0 0" />
      <geometry>
        <mesh
          filename="package://scara.SLDASM/meshes/link1.STL" />
      </geometry>
    </collision>
  </link>
  <joint
    name="joint1"
    type="prismatic">
    <origin
      xyz="0 0 0"
      rpy="0 0 0" />
    <parent
      link="base_link" />
    <child
      link="link1" />
    <axis
      xyz="0 0 1" />
    <limit
      lower="0"
      upper="0.75"
      effort="1000"
      velocity="0.14" />
  </joint>
  <link
    name="link2">
    <inertial>
      <origin
        xyz="0.075 2.4286E-17 0.025555"
        rpy="0 0 0" />
      <mass
        value="0.46727" />
      <inertia
        ixx="0.00018525"
        ixy="-6.6407E-19"
        ixz="1.6028E-21"
        iyy="0.0015347"
        iyz="9.1856E-20"
        izz="0.0015228" />
    </inertial>
    <visual>
      <origin
        xyz="0 0 0"
        rpy="0 0 0" />
      <geometry>
        <mesh
          filename="package://scara.SLDASM/meshes/link2.STL" />
      </geometry>
      <material
        name="">
        <color
          rgba="1 1 1 1" />
      </material>
    </visual>
    <collision>
      <origin
        xyz="0 0 0"
        rpy="0 0 0" />
      <geometry>
        <mesh
          filename="package://scara.SLDASM/meshes/link2.STL" />
      </geometry>
    </collision>
  </link>
  <joint
    name="joint2"
    type="revolute">
    <origin
      xyz="0.03 0 0.0175"
      rpy="0 0 0" />
    <parent
      link="link1" />
    <child
      link="link2" />
    <axis
      xyz="0 0 -1" />
    <limit
      lower="-1.5708"
      upper="1.5708"
      effort="200"
      velocity="8" />
  </joint>
  <link
    name="link3">
    <inertial>
      <origin
        xyz="0.095245 4.7914E-07 -0.0060558"
        rpy="0 0 0" />
      <mass
        value="0.26168" />
      <inertia
        ixx="8.9652E-05"
        ixy="2.6683E-10"
        ixz="-8.5338E-05"
        iyy="0.00087492"
        iyz="5.2233E-10"
        izz="0.00088422" />
    </inertial>
    <visual>
      <origin
        xyz="0 0 0"
        rpy="0 0 0" />
      <geometry>
        <mesh
          filename="package://scara.SLDASM/meshes/link3.STL" />
      </geometry>
      <material
        name="">
        <color
          rgba="1 1 1 1" />
      </material>
    </visual>
    <collision>
      <origin
        xyz="0 0 0"
        rpy="0 0 0" />
      <geometry>
        <mesh
          filename="package://scara.SLDASM/meshes/link3.STL" />
      </geometry>
    </collision>
  </link>
  <joint
    name="joint3"
    type="revolute">
    <origin
      xyz="0.15 0 0"
      rpy="0 0 0" />
    <parent
      link="link2" />
    <child
      link="link3" />
    <axis
      xyz="0 0 -1" />
    <limit
      lower="-2.3562"
      upper="2.3562"
      effort="200"
      velocity="8" />
  </joint>
  <link
    name="link4">
    <inertial>
      <origin
        xyz="-0.0041036 1.0825E-15 -0.034244"
        rpy="0 0 0" />
      <mass
        value="0.069372" />
      <inertia
        ixx="3.6215E-05"
        ixy="-1.7011E-21"
        ixz="-2.4225E-07"
        iyy="2.168E-05"
        iyz="-7.7694E-21"
        izz="2.0672E-05" />
    </inertial>
    <visual>
      <origin
        xyz="0 0 0"
        rpy="0 0 0" />
      <geometry>
        <mesh
          filename="package://scara.SLDASM/meshes/link4.STL" />
      </geometry>
      <material
        name="">
        <color
          rgba="1 1 1 1" />
      </material>
    </visual>
    <collision>
      <origin
        xyz="0 0 0"
        rpy="0 0 0" />
      <geometry>
        <mesh
          filename="package://scara.SLDASM/meshes/link4.STL" />
      </geometry>
    </collision>
  </link>
  <joint
    name="joint4"
    type="revolute">
    <origin
      xyz="0.15 0 -0.024"
      rpy="0 0 0" />
    <parent
      link="link3" />
    <child
      link="link4" />
    <axis
      xyz="0 0 -1" />
    <limit
      lower="-2.3562"
      upper="2.3562"
      effort="200"
      velocity="8" />
  </joint>
  
  <link name="ee_link">
    <visual>
      <origin 
      xyz="0 0 0" 
      rpy="0 0 0"/>
      <geometry>
        <sphere 
        radius="0.01"/>
      </geometry>
    </visual>
  </link>
  
  <joint 
    name="tool0" 
    type="fixed">
    <origin 
      xyz="0.00931 0.00244 -0.05053" 
      rpy="0 0 0"/>
    <parent 
      link="link4"/>
    <child 
      link="ee_link"/>
  </joint>
</robot>
